Workbook
Name activeemp: Analysis1!$I$22
Name attriterate: Analysis1!$I$21
Name attritionrate: Table3[[#Totals],[Attrition Rate]]
Name Avgsalary: Analysis1!$I$27
Name avgscore: Analysis1!$I$28
Name Deptnum: Analysis1!$I$20
Name leftemp: Analysis1!$I$23
Name resignemp: Analysis1!$I$24
Name Slicer_Clean_Employment_Status: #N/A
Name Slicer_Departmental_Name: #N/A
Name sumbonus: Analysis1!$I$29
Name Totalemp: Analysis1!$I$25
Name Totalsalary: Analysis1!$I$26

Sheet Raw_Employee_Data
A1: Emp ID | B1: First_Name | C1: Last_Name | D1: Full_Name | E1: Dept Code | F1: Hire Date | G1: Departmental Name | H1: Clean Hire Date | I1: Salary | J1: Perf_Score | K1: Employment Status | L1: Clean Employment Status | M1: Year of Service | N1: Performance Band | O1: Eligible Bonus Amount
A2: EMP127 | B2: Emily | C2: Brown | D2: =_xlfn.TEXTJOIN(" ", TRUE, B2, C2) -> Emily Brown | E2: IT02 | F2: 43093 | G2: =VLOOKUP(E2, Lookup_Departments!$A$2:$B$6, 2, FALSE) -> Information Technology | H2: =IFERROR(DATEVALUE(F2), F2) -> 43093 | I2: 50361 | J2: 52 | K2: Active | L2: =TRIM(K2) -> Active | M2: =ROUNDDOWN(YEARFRAC(H2, TODAY()), 2) &" " & "Years" -> 8.53 Years | N2: =VLOOKUP(J2, Lookup_Performance!$A$2:$D$6, 3, TRUE) -> Developing | O2: =I2 * VLOOKUP(J2, Lookup_Performance!$A$2:$D$6, 4, TRUE) -> 1007.22
A3: EMP046 | B3: Richard | C3: Hernandez | D3: =_xlfn.TEXTJOIN(" ", TRUE, B3, C3) -> Richard Hernandez | E3: MKT04 | F3: 44659 | G3: =VLOOKUP(E3, Lookup_Departments!$A$2:$B$7, 2, FALSE) -> Marketing | H3: =IFERROR(DATEVALUE(F3), F3) -> 44659 | I3: 112673 | J3: 68.08 | K3: Active | L3: =TRIM(K3) -> Active | M3: =ROUNDDOWN(YEARFRAC(H3, TODAY()), 2) &" " & "Years" -> 4.24 Years | N3: =VLOOKUP(J3, Lookup_Performance!$A$2:$D$6, 3, TRUE) -> Developing | O3: =I3 * VLOOKUP(J3, Lookup_Performance!$A$2:$D$6, 4, TRUE) -> 2253.46
A4: EMP134 | B4: Emily | C4: Gonzalez | D4: =_xlfn.TEXTJOIN(" ", TRUE, B4, C4) -> Emily Gonzalez | E4: IT02 | F4: 42431 | G4: =VLOOKUP(E4, Lookup_Departments!$A$2:$B$7, 2, FALSE) -> Information Technology | H4: =IFERROR(DATEVALUE(F4), F4) -> 42431 | I4: 114425 | J4: 54 | K4: Left | L4: =TRIM(K4) -> Left | M4: =ROUNDDOWN(YEARFRAC(H4, TODAY()), 2) &" " & "Years" -> 10.34 Years | N4: =VLOOKUP(J4, Lookup_Performance!$A$2:$D$6, 3, TRUE) -> Developing | O4: =I4 * VLOOKUP(J4, Lookup_Performance!$A$2:$D$6, 4, TRUE) -> 2288.5
A5: EMP139 | B5: John | C5: Martinez | D5: =_xlfn.TEXTJOIN(" ", TRUE, B5, C5) -> John Martinez | E5: FIN03 | F5: 45110 | G5: =VLOOKUP(E5, Lookup_Departments!$A$2:$B$7, 2, FALSE) -> Finance | H5: =IFERROR(DATEVALUE(F5), F5) -> 45110 | I5: 103831 | J5: 70 | K5: Active | L5: =TRIM(K5) -> Active | M5: =ROUNDDOWN(YEARFRAC(H5, TODAY()), 2) &" " & "Years" -> 3 Years | N5: =VLOOKUP(J5, Lookup_Performance!$A$2:$D$6, 3, TRUE) -> Achieving | O5: =I5 * VLOOKUP(J5, Lookup_Performance!$A$2:$D$6, 4, TRUE) -> 5191.55
A6: EMP112 | B6: Thomas | C6: Smith | D6: =_xlfn.TEXTJOIN(" ", TRUE, B6, C6) -> Thomas Smith | E6: IT02 | F6: 44977 | G6: =VLOOKUP(E6, Lookup_Departments!$A$2:$B$7, 2, FALSE) -> Information Technology | H6: =IFERROR(DATEVALUE(F6), F6) -> 44977 | I6: 73785 | J6: 40 | K6: Left | L6: =TRIM(K6) -> Left | M6: =ROUNDDOWN(YEARFRAC(H6, TODAY()), 2) &" " & "Years" -> 3.37 Years | N6: =VLOOKUP(J6, Lookup_Performance!$A$2:$D$6, 3, TRUE) -> Needs Improvement | O6: =I6 * VLOOKUP(J6, Lookup_Performance!$A$2:$D$6, 4, TRUE) -> 0
A7: EMP030 | B7: Emily | C7: Johnson | D7: =_xlfn.TEXTJOIN(" ", TRUE, B7, C7) -> Emily Johnson | E7: OPS06 | F7: 43892 | G7: =VLOOKUP(E7, Lookup_Departments!$A$2:$B$7, 2, FALSE) -> Operations | H7: =IFERROR(DATEVALUE(F7), F7) -> 43892 | I7: 115882 | J7: 49 | K7: Active | L7: =TRIM(K7) -> Active | M7: =ROUNDDOWN(YEARFRAC(H7, TODAY()), 2) &" " & "Years" -> 6.34 Years | N7: =VLOOKUP(J7, Lookup_Performance!$A$2:$D$6, 3, TRUE) -> Needs Improvement | O7: =I7 * VLOOKUP(J7, Lookup_Performance!$A$2:$D$6, 4, TRUE) -> 0
A8: EMP096 | B8: John | C8: Wilson | D8: =_xlfn.TEXTJOIN(" ", TRUE, B8, C8) -> John Wilson | E8: OPS06 | F8: 45272 | G8: =VLOOKUP(E8, Lookup_Departments!$A$2:$B$7, 2, FALSE) -> Operations | H8: =IFERROR(DATEVALUE(F8), F8) -> 45272 | I8: 59980 | J8: 70 | K8: Left | L8: =TRIM(K8) -> Left | M8: =ROUNDDOWN(YEARFRAC(H8, TODAY()), 2) &" " & "Years" -> 2.56 Years | N8: =VLOOKUP(J8, Lookup_Performance!$A$2:$D$6, 3, TRUE) -> Achieving | O8: =I8 * VLOOKUP(J8, Lookup_Performance!$A$2:$D$6, 4, TRUE) -> 2999
A9: EMP098 | B9: Jessica | C9: Smith | D9: =_xlfn.TEXTJOIN(" ", TRUE, B9, C9) -> Jessica Smith | E9: OPS06 | F9: 44174 | G9: =VLOOKUP(E9, Lookup_Departments!$A$2:$B$7, 2, FALSE) -> Operations | H9: =IFERROR(DATEVALUE(F9), F9) -> 44174 | I9: 68728 | J9: 45 | K9: Active | L9: =TRIM(K9) -> Active | M9: =ROUNDDOWN(YEARFRAC(H9, TODAY()), 2) &" " & "Years" -> 5.57 Years | N9: =VLOOKUP(J9, Lookup_Performance!$A$2:$D$6, 3, TRUE) -> Needs Improvement | O9: =I9 * VLOOKUP(J9, Lookup_Performance!$A$2:$D$6, 4, TRUE) -> 0
A10: EMP095 | C10: Rodriguez | D10: =_xlfn.TEXTJOIN(" ", TRUE, B10, C10) -> Rodriguez | E10: FIN03 | F10: 43107 | G10: =VLOOKUP(E10, Lookup_Departments!$A$2:$B$7, 2, FALSE) -> Finance | H10: =IFERROR(DATEVALUE(F10), F10) -> 43107 | I10: 102139 | J10: 79 | K10: Active | L10: =TRIM(K10) -> Active | M10: =ROUNDDOWN(YEARFRAC(H10, TODAY()), 2) &" " & "Years" -> 8.49 Years | N10: =VLOOKUP(J10, Lookup_Performance!$A$2:$D$6, 3, TRUE) -> Achieving | O10: =I10 * VLOOKUP(J10, Lookup_Performance!$A$2:$D$6, 4, TRUE) -> 5106.95
A11: EMP140 | B11: Michael | C11: Martinez | D11: =_xlfn.TEXTJOIN(" ", TRUE, B11, C11) -> Michael Martinez | E11: SAL05 | F11: 42676 | G11: =VLOOKUP(E11, Lookup_Departments!$A$2:$B$7, 2, FALSE) -> Sales | H11: =IFERROR(DATEVALUE(F11), F11) -> 42676 | I11: 94998 | J11: 58 | K11: Active | L11: =TRIM(K11) -> Active | M11: =ROUNDDOWN(YEARFRAC(H11, TODAY()), 2) &" " & "Years" -> 9.67 Years | N11: =VLOOKUP(J11, Lookup_Performance!$A$2:$D$6, 3, TRUE) -> Developing | O11: =I11 * VLOOKUP(J11, Lookup_Performance!$A$2:$D$6, 4, TRUE) -> 1899.96
A12: EMP020 | B12: Emily | C12: Miller | D12: =_xlfn.TEXTJOIN(" ", TRUE, B12, C12) -> Emily Miller | E12: SAL05 | F12: 43911 | G12: =VLOOKUP(E12, Lookup_Departments!$A$2:$B$7, 2, FALSE) -> Sales | H12: =IFERROR(DATEVALUE(F12), F12) -> 43911 | I12: 118635 | J12: 49 | K12: Active | L12: =TRIM(K12) -> Active | M12: =ROUNDDOWN(YEARFRAC(H12, TODAY()), 2) &" " & "Years" -> 6.29 Years | N12: =VLOOKUP(J12, Lookup_Performance!$A$2:$D$6, 3, TRUE) -> Needs Improvement | O12: =I12 * VLOOKUP(J12, Lookup_Performance!$A$2:$D$6, 4, TRUE) -> 0
A13: EMP057 | B13: Emily | C13: Hernandez | D13: =_xlfn.TEXTJOIN(" ", TRUE, B13, C13) -> Emily Hernandez | E13: IT02 | F13: 42425 | G13: =VLOOKUP(E13, Lookup_Departments!$A$2:$B$7, 2, FALSE) -> Information Technology | H13: =IFERROR(DATEVALUE(F13), F13) -> 42425 | I13: 76918 | J13: 62 | K13: Active | L13: =TRIM(K13) -> Active | M13: =ROUNDDOWN(YEARFRAC(H13, TODAY()), 2) &" " & "Years" -> 10.36 Years | N13: =VLOOKUP(J13, Lookup_Performance!$A$2:$D$6, 3, TRUE) -> Developing | O13: =I13 * VLOOKUP(J13, Lookup_Performance!$A$2:$D$6, 4, TRUE) -> 1538.36
A14: EMP016 | B14: Jane | C14: Williams | D14: =_xlfn.TEXTJOIN(" ", TRUE, B14, C14) -> Jane Williams | E14: MKT04 | F14: 44364 | G14: =VLOOKUP(E14, Lookup_Departments!$A$2:$B$7, 2, FALSE) -> Marketing | H14: =IFERROR(DATEVALUE(F14), F14) -> 44364 | I14: 61408 | J14: 48 | K14: Active | L14: =TRIM(K14) -> Active | M14: =ROUNDDOWN(YEARFRAC(H14, TODAY()), 2) &" " & "Years" -> 5.05 Years | N14: =VLOOKUP(J14, Lookup_Performance!$A$2:$D$6, 3, TRUE) -> Needs Improvement | O14: =I14 * VLOOKUP(J14, Lookup_Performance!$A$2:$D$6, 4, TRUE) -> 0
A15: EMP070 | B15: Jane | C15: Miller | D15: =_xlfn.TEXTJOIN(" ", TRUE, B15, C15) -> Jane Miller | E15: MKT04 | F15: 44001 | G15: =VLOOKUP(E15, Lookup_Departments!$A$2:$B$7, 2, FALSE) -> Marketing | H15: =IFERROR(DATEVALUE(F15), F15) -> 44001 | I15: 99990 | J15: 54 | K15: Active | L15: =TRIM(K15) -> Active | M15: =ROUNDDOWN(YEARFRAC(H15, TODAY()), 2) &" " & "Years" -> 6.04 Years | N15: =VLOOKUP(J15, Lookup_Performance!$A$2:$D$6, 3, TRUE) -> Developing | O15: =I15 * VLOOKUP(J15, Lookup_Performance!$A$2:$D$6, 4, TRUE) -> 1999.8
A16: EMP025 | B16: Robert | C16: Jones | D16: =_xlfn.TEXTJOIN(" ", TRUE, B16, C16) -> Robert Jones | E16: MKT04 | F16: 43820 | G16: =VLOOKUP(E16, Lookup_Departments!$A$2:$B$7, 2, FALSE) -> Marketing | H16: =IFERROR(DATEVALUE(F16), F16) -> 43820 | I16: 80385 | J16: 68.08 | K16: Active | L16: =TRIM(K16) -> Active | M16: =ROUNDDOWN(YEARFRAC(H16, TODAY()), 2) &" " & "Years" -> 6.54 Years | N16: =VLOOKUP(J16, Lookup_Performance!$A$2:$D$6, 3, TRUE) -> Developing | O16: =I16 * VLOOKUP(J16, Lookup_Performance!$A$2:$D$6, 4, TRUE) -> 1607.7
A17: EMP031 | B17: Thomas | C17: Rodriguez | D17: =_xlfn.TEXTJOIN(" ", TRUE, B17, C17) -> Thomas Rodriguez | E17: SAL05 | F17: 45169 | G17: =VLOOKUP(E17, Lookup_Departments!$A$2:$B$7, 2, FALSE) -> Sales | H17: =IFERROR(DATEVALUE(F17), F17) -> 45169 | I17: 65290 | J17: 77 | K17: Active | L17: =TRIM(K17) -> Active | M17: =ROUNDDOWN(YEARFRAC(H17, TODAY()), 2) &" " & "Years" -> 2.85 Years | N17: =VLOOKUP(J17, Lookup_Performance!$A$2:$D$6, 3, TRUE) -> Achieving | O17: =I17 * VLOOKUP(J17, Lookup_Performance!$A$2:$D$6, 4, TRUE) -> 3264.5
A18: EMP126 | B18: Emily | C18: Davis | D18: =_xlfn.TEXTJOIN(" ", TRUE, B18, C18) -> Emily Davis | E18: IT02 | F18: 42337 | G18: =VLOOKUP(E18, Lookup_Departments!$A$2:$B$7, 2, FALSE) -> Information Technology | H18: =IFERROR(DATEVALUE(F18), F18) -> 42337 | I18: 105765 | J18: 42 | K18: Active | L18: =TRIM(K18) -> Active | M18: =ROUNDDOWN(YEARFRAC(H18, TODAY()), 2) &" " & "Years" -> 10.6 Years | N18: =VLOOKUP(J18, Lookup_Performance!$A$2:$D$6, 3, TRUE) -> Needs Improvement | O18: =I18 * VLOOKUP(J18, Lookup_Performance!$A$2:$D$6, 4, TRUE) -> 0
A19: EMP109 | B19: James | C19: Martinez | D19: =_xlfn.TEXTJOIN(" ", TRUE, B19, C19) -> James Martinez | E19: SAL05 | F19: 42899 | G19: =VLOOKUP(E19, Lookup_Departments!$A$2:$B$7, 2, FALSE) -> Sales | H19: =IFERROR(DATEVALUE(F19), F19) -> 42899 | I19: 102921 | J19: 49 | K19: Active | L19: =TRIM(K19) -> Active | M19: =ROUNDDOWN(YEARFRAC(H19, TODAY()), 2) &" " & "Years" -> 9.06 Years | N19: =VLOOKUP(J19, Lookup_Performance!$A$2:$D$6, 3, TRUE) -> Needs Improvement | O19: =I19 * VLOOKUP(J19, Lookup_Performance!$A$2:$D$6, 4, TRUE) -> 0
A20: EMP066 | B20: Ashley | C20: Lopez | D20: =_xlfn.TEXTJOIN(" ", TRUE, B20, C20) -> Ashley Lopez | E20: MKT04 | F20: 43235 | G20: =VLOOKUP(E20, Lookup_Departments!$A$2:$B$7, 2, FALSE) -> Marketing | H20: =IFERROR(DATEVALUE(F20), F20) -> 43235 | I20: 73984 | J20: 93 | K20: Active | L20: =TRIM(K20) -> Active | M20: =ROUNDDOWN(YEARFRAC(H20, TODAY()), 2) &" " & "Years" -> 8.14 Years | N20: =VLOOKUP(J20, Lookup_Performance!$A$2:$D$6, 3, TRUE) -> Exceeding | O20: =I20 * VLOOKUP(J20, Lookup_Performance!$A$2:$D$6, 4, TRUE) -> 5918.72
A21: EMP120 | B21: Amanda | C21: Gonzalez | D21: =_xlfn.TEXTJOIN(" ", TRUE, B21, C21) -> Amanda Gonzalez | E21: IT02 | F21: 42575 | G21: =VLOOKUP(E21, Lookup_Departments!$A$2:$B$7, 2, FALSE) -> Information Technology | H21: =IFERROR(DATEVALUE(F21), F21) -> 42575 | I21: 83603.93 | J21: 75 | K21: Active | L21: =TRIM(K21) -> Active | M21: =ROUNDDOWN(YEARFRAC(H21, TODAY()), 2) &" " & "Years" -> 9.95 Years | N21: =VLOOKUP(J21, Lookup_Performance!$A$2:$D$6, 3, TRUE) -> Achieving | O21: =I21 * VLOOKUP(J21, Lookup_Performance!$A$2:$D$6, 4, TRUE) -> 4180.1965
A22: EMP019 | B22: Michael | C22: Hernandez | D22: =_xlfn.TEXTJOIN(" ", TRUE, B22, C22) -> Michael Hernandez | E22: FIN03 | F22: 43076 | G22: =VLOOKUP(E22, Lookup_Departments!$A$2:$B$7, 2, FALSE) -> Finance | H22: =IFERROR(DATEVALUE(F22), F22) -> 43076 | I22: 118527 | J22: 50 | K22: Active | L22: =TRIM(K22) -> Active | M22: =ROUNDDOWN(YEARFRAC(H22, TODAY()), 2) &" " & "Years" -> 8.58 Years | N22: =VLOOKUP(J22, Lookup_Performance!$A$2:$D$6, 3, TRUE) -> Developing | O22: =I22 * VLOOKUP(J22, Lookup_Performance!$A$2:$D$6, 4, TRUE) -> 2370.54
... A26: EMP082 | B26: Ashley | C26: Williams | D26: =_xlfn.TEXTJOIN(" ", TRUE, B26, C26) -> Ashley Williams | E26: SAL05 | F26: 44728 | G26: =VLOOKUP(E26, Lookup_Departments!$A$2:$B$7, 2, FALSE) -> Sales | H26: =IFERROR(DATEVALUE(F26), F26) -> 44728 | I26: 68655 | J26: 32 | K26: Active | L26: =TRIM(K26) -> Active | M26: =ROUNDDOWN(YEARFRAC(H26, TODAY()), 2) &" " & "Years" -> 4.05 Years | N26: =VLOOKUP(J26, Lookup_Performance!$A$2:$D$6, 3, TRUE) -> Needs Improvement | O26: =I26 * VLOOKUP(J26, Lookup_Performance!$A$2:$D$6, 4, TRUE) -> 0
A27: EMP052 | C27: Williams | D27: =_xlfn.TEXTJOIN(" ", TRUE, B27, C27) -> Williams | E27: SAL05 | F27: 45134 | G27: =VLOOKUP(E27, Lookup_Departments!$A$2:$B$7, 2, FALSE) -> Sales | H27: =IFERROR(DATEVALUE(F27), F27) -> 45134 | I27: 81205 | J27: 59 | K27: Active | L27: =TRIM(K27) -> Active | M27: =ROUNDDOWN(YEARFRAC(H27, TODAY()), 2) &" " & "Years" -> 2.94 Years | N27: =VLOOKUP(J27, Lookup_Performance!$A$2:$D$6, 3, TRUE) -> Developing | O27: =I27 * VLOOKUP(J27, Lookup_Performance!$A$2:$D$6, 4, TRUE) -> 1624.1
A28: EMP129 | B28: John | C28: Wilson | D28: =_xlfn.TEXTJOIN(" ", TRUE, B28, C28) -> John Wilson | E28: SAL05 | F28: 09/24/2019 | G28: =VLOOKUP(E28, Lookup_Departments!$A$2:$B$7, 2, FALSE) -> Sales | H28: =IFERROR(DATEVALUE(F28), F28) -> 43732 | I28: 77610 | J28: 88 | K28: Active | L28: =TRIM(K28) -> Active | M28: =ROUNDDOWN(YEARFRAC(H28, TODAY()), 2) &" " & "Years" -> 6.78 Years | N28: =VLOOKUP(J28, Lookup_Performance!$A$2:$D$6, 3, TRUE) -> Exceeding | O28: =I28 * VLOOKUP(J28, Lookup_Performance!$A$2:$D$6, 4, TRUE) -> 6208.8
A29: EMP146 | B29: Thomas | C29: Rodriguez | D29: =_xlfn.TEXTJOIN(" ", TRUE, B29, C29) -> Thomas Rodriguez | E29: IT02 | F29: 44765 | G29: =VLOOKUP(E29, Lookup_Departments!$A$2:$B$7, 2, FALSE) -> Information Technology | H29: =IFERROR(DATEVALUE(F29), F29) -> 44765 | I29: 50873 | J29: 90 | K29: Active | L29: =TRIM(K29) -> Active | M29: =ROUNDDOWN(YEARFRAC(H29, TODAY()), 2) &" " & "Years" -> 3.95 Years | N29: =VLOOKUP(J29, Lookup_Performance!$A$2:$D$6, 3, TRUE) -> Exceeding | O29: =I29 * VLOOKUP(J29, Lookup_Performance!$A$2:$D$6, 4, TRUE) -> 4069.84
A30: EMP099 | B30: Michael | C30: Wilson | D30: =_xlfn.TEXTJOIN(" ", TRUE, B30, C30) -> Michael Wilson | E30: FIN03 | F30: 13-May-18 | G30: =VLOOKUP(E30, Lookup_Departments!$A$2:$B$7, 2, FALSE) -> Finance | H30: =IFERROR(DATEVALUE(F30), F30) -> 43233 | I30: 85312 | J30: 66 | K30: Active | L30: =TRIM(K30) -> Active | M30: =ROUNDDOWN(YEARFRAC(H30, TODAY()), 2) &" " & "Years" -> 8.14 Years | N30: =VLOOKUP(J30, Lookup_Performance!$A$2:$D$6, 3, TRUE) -> Developing | O30: =I30 * VLOOKUP(J30, Lookup_Performance!$A$2:$D$6, 4, TRUE) -> 1706.24
A31: EMP015 | B31: John | C31: Rodriguez | D31: =_xlfn.TEXTJOIN(" ", TRUE, B31, C31) -> John Rodriguez | E31: SAL05 | F31: 42202 | G31: =VLOOKUP(E31, Lookup_Departments!$A$2:$B$7, 2, FALSE) -> Sales | H31: =IFERROR(DATEVALUE(F31), F31) -> 42202 | I31: 83603.93 | J31: 68 | K31: Active | L31: =TRIM(K31) -> Active | M31: =ROUNDDOWN(YEARFRAC(H31, TODAY()), 2) &" " & "Years" -> 10.96 Years | N31: =VLOOKUP(J31, Lookup_Performance!$A$2:$D$6, 3, TRUE) -> Developing | O31: =I31 * VLOOKUP(J31, Lookup_Performance!$A$2:$D$6, 4, TRUE) -> 1672.0786
A32: EMP076 | B32: Thomas | C32: Hernandez | D32: =_xlfn.TEXTJOIN(" ", TRUE, B32, C32) -> Thomas Hernandez | E32: OPS06 | F32: 05-Aug-15 | G32: =VLOOKUP(E32, Lookup_Departments!$A$2:$B$7, 2, FALSE) -> Operations | H32: =IFERROR(DATEVALUE(F32), F32) -> 42221 | I32: 97055 | J32: 80 | K32: Active | L32: =TRIM(K32) -> Active | M32: =ROUNDDOWN(YEARFRAC(H32, TODAY()), 2) &" " & "Years" -> 10.91 Years | N32: =VLOOKUP(J32, Lookup_Performance!$A$2:$D$6, 3, TRUE) -> Achieving | O32: =I32 * VLOOKUP(J32, Lookup_Performance!$A$2:$D$6, 4, TRUE) -> 4852.75
A33: EMP137 | B33: Michael | C33: Johnson | D33: =_xlfn.TEXTJOIN(" ", TRUE, B33, C33) -> Michael Johnson | E33: IT02 | F33: 45195 | G33: =VLOOKUP(E33, Lookup_Departments!$A$2:$B$7, 2, FALSE) -> Information Technology | H33: =IFERROR(DATEVALUE(F33), F33) -> 45195 | I33: 66069 | J33: 72 | K33: Active | L33: =TRIM(K33) -> Active | M33: =ROUNDDOWN(YEARFRAC(H33, TODAY()), 2) &" " & "Years" -> 2.77 Years | N33: =VLOOKUP(J33, Lookup_Performance!$A$2:$D$6, 3, TRUE) -> Achieving | O33: =I33 * VLOOKUP(J33, Lookup_Performance!$A$2:$D$6, 4, TRUE) -> 3303.45
A34: EMP056 | B34: Sarah | C34: Brown | D34: =_xlfn.TEXTJOIN(" ", TRUE, B34, C34) -> Sarah Brown | E34: IT02 | F34: 10-Jun-19 | G34: =VLOOKUP(E34, Lookup_Departments!$A$2:$B$7, 2, FALSE) -> Information Technology | H34: =IFERROR(DATEVALUE(F34), F34) -> 43626 | I34: 90157 | J34: 58 | K34: Active | L34: =TRIM(K34) -> Active | M34: =ROUNDDOWN(YEARFRAC(H34, TODAY()), 2) &" " & "Years" -> 7.07 Years | N34: =VLOOKUP(J34, Lookup_Performance!$A$2:$D$6, 3, TRUE) -> Developing | O34: =I34 * VLOOKUP(J34, Lookup_Performance!$A$2:$D$6, 4, TRUE) -> 1803.14
A35: EMP125 | B35: Jane | C35: Martinez | D35: =_xlfn.TEXTJOIN(" ", TRUE, B35, C35) -> Jane Martinez | E35: HR01 | F35: 44578 | G35: =VLOOKUP(E35, Lookup_Departments!$A$2:$B$7, 2, FALSE) -> Human Resources | H35: =IFERROR(DATEVALUE(F35), F35) -> 44578 | I35: 59899 | J35: 78 | K35: Active | L35: =TRIM(K35) -> Active | M35: =ROUNDDOWN(YEARFRAC(H35, TODAY()), 2) &" " & "Years" -> 4.46 Years | N35: =VLOOKUP(J35, Lookup_Performance!$A$2:$D$6, 3, TRUE) -> Achieving | O35: =I35 * VLOOKUP(J35, Lookup_Performance!$A$2:$D$6, 4, TRUE) -> 2994.95
A36: EMP085 | B36: Emily | C36: Jones | D36: =_xlfn.TEXTJOIN(" ", TRUE, B36, C36) -> Emily Jones | E36: FIN03 | F36: 03-Jul-17 | G36: =VLOOKUP(E36, Lookup_Departments!$A$2:$B$7, 2, FALSE) -> Finance | H36: =IFERROR(DATEVALUE(F36), F36) -> 42919 | I36: 113389 | J36: 30 | K36: Active | L36: =TRIM(K36) -> Active | M36: =ROUNDDOWN(YEARFRAC(H36, TODAY()), 2) &" " & "Years" -> 9 Years | N36: =VLOOKUP(J36, Lookup_Performance!$A$2:$D$6, 3, TRUE) -> Needs Improvement | O36: =I36 * VLOOKUP(J36, Lookup_Performance!$A$2:$D$6, 4, TRUE) -> 0
A37: EMP106 | C37: Brown | D37: =_xlfn.TEXTJOIN(" ", TRUE, B37, C37) -> Brown | E37: IT02 | F37: 01-Sep-15 | G37: =VLOOKUP(E37, Lookup_Departments!$A$2:$B$7, 2, FALSE) -> Information Technology | H37: =IFERROR(DATEVALUE(F37), F37) -> 42248 | I37: 102691 | J37: 52 | K37: Active | L37: =TRIM(K37) -> Active | M37: =ROUNDDOWN(YEARFRAC(H37, TODAY()), 2) &" " & "Years" -> 10.84 Years | N37: =VLOOKUP(J37, Lookup_Performance!$A$2:$D$6, 3, TRUE) -> Developing | O37: =I37 * VLOOKUP(J37, Lookup_Performance!$A$2:$D$6, 4, TRUE) -> 2053.82
A38: EMP043 | B38: John | C38: Wilson | D38: =_xlfn.TEXTJOIN(" ", TRUE, B38, C38) -> John Wilson | E38: OPS06 | F38: 03-Aug-22 | G38: =VLOOKUP(E38, Lookup_Departments!$A$2:$B$7, 2, FALSE) -> Operations | H38: =IFERROR(DATEVALUE(F38), F38) -> 44776 | I38: 111845 | J38: 98 | K38: Active | L38: =TRIM(K38) -> Active | M38: =ROUNDDOWN(YEARFRAC(H38, TODAY()), 2) &" " & "Years" -> 3.92 Years | N38: =VLOOKUP(J38, Lookup_Performance!$A$2:$D$6, 3, TRUE) -> Outstanding | O38: =I38 * VLOOKUP(J38, Lookup_Performance!$A$2:$D$6, 4, TRUE) -> 13421.4
A39: EMP068 | B39: Melissa | C39: Brown | D39: =_xlfn.TEXTJOIN(" ", TRUE, B39, C39) -> Melissa Brown | E39: SAL05 | F39: 06/29/2022 | G39: =VLOOKUP(E39, Lookup_Departments!$A$2:$B$7, 2, FALSE) -> Sales | H39: =IFERROR(DATEVALUE(F39), F39) -> 44741 | I39: 69219 | J39: 93 | K39: Active | L39: =TRIM(K39) -> Active | M39: =ROUNDDOWN(YEARFRAC(H39, TODAY()), 2) &" " & "Years" -> 4.01 Years | N39: =VLOOKUP(J39, Lookup_Performance!$A$2:$D$6, 3, TRUE) -> Exceeding | O39: =I39 * VLOOKUP(J39, Lookup_Performance!$A$2:$D$6, 4, TRUE) -> 5537.52
A40: EMP128 | B40: Michael | C40: Smith | D40: =_xlfn.TEXTJOIN(" ", TRUE, B40, C40) -> Michael Smith | E40: FIN03 | F40: 43949 | G40: =VLOOKUP(E40, Lookup_Departments!$A$2:$B$7, 2, FALSE) -> Finance | H40: =IFERROR(DATEVALUE(F40), F40) -> 43949 | I40: 83603.93 | J40: 80 | K40: Left | L40: =TRIM(K40) -> Left | M40: =ROUNDDOWN(YEARFRAC(H40, TODAY()), 2) &" " & "Years" -> 6.18 Years | N40: =VLOOKUP(J40, Lookup_Performance!$A$2:$D$6, 3, TRUE) -> Achieving | O40: =I40 * VLOOKUP(J40, Lookup_Performance!$A$2:$D$6, 4, TRUE) -> 4180.1965
A41: EMP027 | B41: Sarah | C41: Miller | D41: =_xlfn.TEXTJOIN(" ", TRUE, B41, C41) -> Sarah Miller | E41: OPS06 | F41: 09/09/2017 | G41: =VLOOKUP(E41, Lookup_Departments!$A$2:$B$7, 2, FALSE) -> Operations | H41: =IFERROR(DATEVALUE(F41), F41) -> 42987 | I41: 57514 | J41: 68.08 | K41: Active | L41: =TRIM(K41) -> Active | M41: =ROUNDDOWN(YEARFRAC(H41, TODAY()), 2) &" " & "Years" -> 8.82 Years | N41: =VLOOKUP(J41, Lookup_Performance!$A$2:$D$6, 3, TRUE) -> Developing | O41: =I41 * VLOOKUP(J41, Lookup_Performance!$A$2:$D$6, 4, TRUE) -> 1150.28
A42: EMP136 | B42: Emily | C42: Wilson | D42: =_xlfn.TEXTJOIN(" ", TRUE, B42, C42) -> Emily Wilson | E42: SAL05 | F42: 43181 | G42: =VLOOKUP(E42, Lookup_Departments!$A$2:$B$7, 2, FALSE) -> Sales | H42: =IFERROR(DATEVALUE(F42), F42) -> 43181 | I42: 86245 | J42: 71 | K42: Left | L42: =TRIM(K42) -> Left | M42: =ROUNDDOWN(YEARFRAC(H42, TODAY()), 2) &" " & "Years" -> 8.28 Years | N42: =VLOOKUP(J42, Lookup_Performance!$A$2:$D$6, 3, TRUE) -> Achieving | O42: =I42 * VLOOKUP(J42, Lookup_Performance!$A$2:$D$6, 4, TRUE) -> 4312.25
A43: EMP079 | B43: David | C43: Hernandez | D43: =_xlfn.TEXTJOIN(" ", TRUE, B43, C43) -> David Hernandez | E43: SAL05 | F43: 43958 | G43: =VLOOKUP(E43, Lookup_Departments!$A$2:$B$7, 2, FALSE) -> Sales | H43: =IFERROR(DATEVALUE(F43), F43) -> 43958 | I43: 52407 | J43: 55 | K43: Active | L43: =TRIM(K43) -> Active | M43: =ROUNDDOWN(YEARFRAC(H43, TODAY()), 2) &" " & "Years" -> 6.16 Years | N43: =VLOOKUP(J43, Lookup_Performance!$A$2:$D$6, 3, TRUE) -> Developing | O43: =I43 * VLOOKUP(J43, Lookup_Performance!$A$2:$D$6, 4, TRUE) -> 1048.14
...

Sheet Lookup_Departments
A1: Dept_Code | B1: Department_Name
A2: HR01 | B2: Human Resources
A3: IT02 | B3: Information Technology
A4: FIN03 | B4: Finance
A5: MKT04 | B5: Marketing
A6: SAL05 | B6: Sales
A7: OPS06 | B7: Operations

Sheet Lookup_Performance
A1: Min_Score | B1: Max_Score | C1: Performance_Band | D1: Bonus_Percentage
A2: 0 | B2: 49 | C2: Needs Improvement | D2: 0
A3: 50 | B3: 69 | C3: Developing | D3: 0.02
A4: 70 | B4: 84 | C4: Achieving | D4: 0.05
A5: 85 | B5: 94 | C5: Exceeding | D5: 0.08
A6: 95 | B6: 100 | C6: Outstanding | D6: 0.12

Sheet Analysis1
A2: Head Count and Average Salary by Department
A3: Row Labels | B3: Count of Emp ID | C3: Average of Salary | F3: Count of Emp ID | G3: Sum of Salary | H3: Average of Salary | I3: Average of Perf_Score | J3: Sum of Eligible Bonus Amount
A4: Finance | B4: 17 | C4: 87173.576 | F4: 150 | G4: 12540590 | H4: 83603.931 | I4: 68.0776 | J4: 486911.14
A5: Human Resources | B5: 18 | C5: 85536.274
A6: Information Technology | B6: 36 | C6: 80512.824
A7: Marketing | B7: 19 | C7: 85407.944
A8: Operations | B8: 29 | C8: 80049.926 | I8: Row Labels | J8: Count of Emp ID
A9: Sales | B9: 31 | C9: 86333.079 | I9: Active | J9: 116
A10: Grand Total | B10: 150 | C10: 83603.931 | I10: Left | J10: 24
I11: Resigned | J11: 10
I12: Grand Total | J12: 150
A14: Attrition rate by Department
A15: Count of Emp ID | B15: Column Labels
A16: Row Labels | B16: Active | C16: Left | D16: Resigned | E16: Grand Total | F16: Attrition Rate
A17: Finance | B17: 14 | C17: 3 | E17: 17 | F17: =C17/E17 -> 0.17647059
A18: Human Resources | B18: 15 | C18: 2 | D18: 1 | E18: 18 | F18: =C18/E18 -> 0.11111111
A19: Information Technology | B19: 28 | C19: 6 | D19: 2 | E19: 36 | F19: =C19/E19 -> 0.16666667
A20: Marketing | B20: 16 | C20: 3 | E20: 19 | F20: =C20/E20 -> 0.15789474 | H20: Num of Dept | I20: =A60 -> 0
A21: Operations | B21: 18 | C21: 6 | D21: 5 | E21: 29 | F21: =C21/E21 -> 0.20689655 | H21: Attrition Rate | I21: =K39 -> 0.21601882
A22: Sales | B22: 25 | C22: 4 | D22: 2 | E22: 31 | F22: =C22/E22 -> 0.12903226 | H22: Active Employees | I22: =J9 -> 116
A23: Grand Total | B23: 116 | C23: 24 | D23: 10 | E23: 150 | F23: =AVERAGE(F17:F22) -> 0.15801199 | H23: Left Employees | I23: =J10 -> 24
H24: Resigned Employess | I24: =J11 -> 10
H25: Total Employees | I25: =F4 -> 150
H26: Total Salaries | I26: =G4 -> 12540590
A27: Average Performance Score | H27: Average Salary | I27: =H4 -> 83603.931
A28: Row Labels | B28: Average of Perf_Score | H28: Perf Score | I28: =I4 -> 68.0776
A29: Active | B29: 67.746207 | H29: Total Bonus | I29: =J4 -> 486911.14
A30: Left | B30: 66.211667
A31: Resigned | B31: 76.4
A32: Grand Total | B32: 68.0776 | H32: Departments | I32: Total Exits | J32: Grand Total | K32: Attrition Rate
H33: Finance | I33: =SUM(C17:D17) -> 3 | J33: 17 | K33: =I33/J33 -> 0.17647059
H34: Human Resources | I34: =SUM(C18:D18) -> 3 | J34: 18 | K34: =I34/J34 -> 0.16666667
H35: Information Technology | I35: =SUM(C19:D19) -> 8 | J35: 36 | K35: =I35/J35 -> 0.22222222
A36: Bonus Payout by Performance | H36: Marketing | I36: =SUM(C20:D20) -> 3 | J36: 19 | K36: =I36/J36 -> 0.15789474
A37: Row Labels | B37: Sum of Eligible Bonus Amount | H37: Operations | I37: =SUM(C21:D21) -> 11 | J37: 29 | K37: =I37/J37 -> 0.37931034
A38: Achieving | B38: 165216.93 | H38: Sales | I38: =SUM(C22:D22) -> 6 | J38: 31 | K38: =I38/J38 -> 0.19354839
A39: Developing | B39: 84593.269 | K39: =AVERAGE(Table3[Attrition Rate]) -> 0.21601882
A40: Exceeding | B40: 144689.43
A41: Needs Improvement | B41: 0
A42: Outstanding | B42: 92411.512
...

Sheet HR Dashboard
